Workbook

Sheet Read me
A1: Gym Floor Plan to 3D Walkthrough: task plan
A3: Purpose | B3: Every task from the build plan (Gym-Floor-Plan-3D-Build-Plan.docx), what it involves and who does it. No dates or estimates by design.
A4: Reviewed code | B4: All tasks were audited at commit 1316d60. Tejesh's tasks were re-checked at 91c737d (GitHub main); Thomas's statuses have not been re-checked since his two newer commits.
A5: Tejesh in order | B5: Tejesh's 33 tasks in the order to do them, one by one. Its Status column reads the Task plan sheet, so update the status there.
A6: TRELLIS check | B6: The Digital Twin's image-to-3D code compared line by line with Microsoft's TRELLIS and TRELLIS.2 code, plus the licence of everything it loads.
A7: How to use | B7: Filter the Task plan sheet by Owner or Area. Keep Status today up to date using its dropdown; the Summary sheet counts update by themselves.
A8: Cells to edit | B8: Task plan: Status today (column G), Owner (E), Works with (F), Notes (I). Leave ID and Area as they are; add new tasks at the bottom.
A9: Status values | B9: Not started · Partly built (some code exists, see Notes) · In progress · Done · Blocked
A10: Tejesh | B10: 2D to 3D generation, the 3D walkthrough viewer and machine 3D models from the 360° video. Backend and web only; no iPhone work.
A11: Thomas | B11: Everything else: iPhone app, single sign-in, database, backend services, processing pipeline, scan to 2D plan, plan format, reviewer editor, deployment.
A12: GoalCert team | B12: Hub organisation, product registration, DNS, hosting region, user-creation API.
A13: Product owner | B13: Decisions, PRD addendum, reference gyms, Apple account, Mac and test devices.
A14: Legal | B14: TRELLIS.2 licence review.
A15: Other sheets | B15: Summary · TRELLIS check · Database findings · Target schema · 2D plan for 3D · Sign-in review

Sheet Tejesh in order
A1: Tejesh: tasks in the order to do them
A2: Backend and web only. Status comes from the Task plan sheet; change it there.
A4: Building the 3D walkthrough (2D to 3D)
A5: Step | B5: ID | C5: Task | D5: Description | E5: Status today | F5: Depends on | G5: Notes
A6: 1 | B6: G-01 | C6: Define the 3D contract | D6: Write down every 2D plan field the 3D generator relies on, its unit and what happens when it is missing (section 9). | E6: =IFERROR(INDEX('Task plan'!$G$2:$G$500,MATCH($B6,'Task plan'!$A$2:$A$500,0)),"") | G6: gymplan/3 in shared/plan/model.js already carries spaces, ceilings, wall kinds, curves, mirror spans, opening kinds and hinges, beams, level changes, voids, machine facing and model reference. Write down units and missing-value rules.
A7: 2 | B7: C-15 | C7: 3D tables | D7: Design and migrate generated_models and machine_models (status, generator version, storage keys, sizes, review) in the shared schema. | E7: =IFERROR(INDEX('Task plan'!$G$2:$G$500,MATCH($B7,'Task plan'!$A$2:$A$500,0)),"") | F7: C-01 | G7: Built by Thomas in backend/migrations/001_baseline.sql (machine_models, generated_models). Review only.
A8: 3 | B8: J-01 | C8: Generator worker | D8: plan.generate job in the backend workers: read the approved plan, build the level model, store it, record it in generated_models. The same plan and generator version always give the same file. | E8: =IFERROR(INDEX('Task plan'!$G$2:$G$500,MATCH($B8,'Task plan'!$A$2:$A$500,0)),"") | F8: E-01, G-01, C-15 | G8: Hook exists: setGenerator() and the plan.generate handler in backend/src/jobs/handlers.js; a placeholder stores no file.
A9: 4 | B9: J-02 | C9: Walls and openings | D9: Walls at their measured thickness and height, including curves; openings cut at their real sill and head; door leaves by kind, hinge and swing; glazing. | E9: =IFERROR(INDEX('Task plan'!$G$2:$G$500,MATCH($B9,'Task plan'!$A$2:$A$500,0)),"") | F9: J-01, G-03, G-04 | G9: Today: 15 cm walls, 2.1 m door head, 0.9–2.1 m windows for every plan.
A10: 5 | B10: J-03 | C10: Spaces, floors and ceilings | D10: Floor and ceiling per space; ceiling zones; beams and bulkheads; steps, platforms and ramps. | E10: =IFERROR(INDEX('Task plan'!$G$2:$G$500,MATCH($B10,'Task plan'!$A$2:$A$500,0)),"") | F10: J-01, G-02, G-05
A11: 6 | B11: J-04 | C11: Stairs, lifts, columns and mirrors | D11: Voids with rails, columns by shape and height, reflective mirror spans. | E11: =IFERROR(INDEX('Task plan'!$G$2:$G$500,MATCH($B11,'Task plan'!$A$2:$A$500,0)),"") | F11: J-01, G-03, G-05
A12: 7 | B12: J-05 | C12: Default finishes | D12: One finish set for floor, wall and ceiling (GEN-03), with floor finish per space. | E12: =IFERROR(INDEX('Task plan'!$G$2:$G$500,MATCH($B12,'Task plan'!$A$2:$A$500,0)),"") | F12: J-01
A13: 8 | B13: J-07 | C13: Tags and zones | D13: Fire exit signs, power points and the no-build zone overlay. | E13: =IFERROR(INDEX('Task plan'!$G$2:$G$500,MATCH($B13,'Task plan'!$A$2:$A$500,0)),"") | F13: J-01
A14: 9 | B14: J-08 | C14: Output format and budget | D14: GLB with compressed geometry (meshopt or Draco) and KTX2 textures, 25 MB or less per level including machines; collision and start-position data alongside. | E14: =IFERROR(INDEX('Task plan'!$G$2:$G$500,MATCH($B14,'Task plan'!$A$2:$A$500,0)),"") | F14: J-01
A15: 10 | B15: J-09 | C15: Generation failures | D15: Mark the job failed with a clear reason so the plan returns to the reviewer queue. | E15: =IFERROR(INDEX('Task plan'!$G$2:$G$500,MATCH($B15,'Task plan'!$A$2:$A$500,0)),"") | F15: E-02
A16: 11 | B16: J-10 | C16: Generator tests | D16: A fixture for each element type; a determinism test (same input, same bytes); a size and speed test on a reference gym. | E16: =IFERROR(INDEX('Task plan'!$G$2:$G$500,MATCH($B16,'Task plan'!$A$2:$A$500,0)),"") | F16: J-01
A17: 12 | B17: M-07 | C17: 3D model delivery | D17: CloudFront with signed URLs for level and machine models. | E17: =IFERROR(INDEX('Task plan'!$G$2:$G$500,MATCH($B17,'Task plan'!$A$2:$A$500,0)),"") | F17: M-03 | G17: infra/lib/models-distribution.ts exists, marked owned by the 3D team, and is wired into data-stack.ts. Signing key pair and URL signing in the API still to do.
A18: 13 | B18: K-01 | C18: Load the generated model | D18: Replace the in-browser build with loading the level file through a signed CloudFront link. | E18: =IFERROR(INDEX('Task plan'!$G$2:$G$500,MATCH($B18,'Task plan'!$A$2:$A$500,0)),"") | F18: J-08, M-07
A19: 14 | B19: K-02 | C19: Keep the viewer features | D19: Walk with collision, touch joystick, overhead view, measure tool, minimap, level switch and the fixed disclaimer, on the generated model. | E19: =IFERROR(INDEX('Task plan'!$G$2:$G$500,MATCH($B19,'Task plan'!$A$2:$A$500,0)),"") | F19: K-01 | G19: All exist today on the browser-built model.
A20: 15 | B20: K-05 | C20: Share-link viewer | D20: The no-sign-in share page shows the same generated model. | E20: =IFERROR(INDEX('Task plan'!$G$2:$G$500,MATCH($B20,'Task plan'!$A$2:$A$500,0)),"") | F20: K-01, D-06
A21: 16 | B21: K-06 | C21: Open the walkthrough from the editor | D21: Reviewers can open a version's generated walkthrough from the editor to check it. | E21: =IFERROR(INDEX('Task plan'!$G$2:$G$500,MATCH($B21,'Task plan'!$A$2:$A$500,0)),"") | F21: K-01
A22: 17 | B22: K-04 | C22: Performance budget | D22: First load under 8 s at 25 Mbps; 30 fps on a 2022 mid-range laptop and a 2021 iPad; checked automatically on a reference gym (VIEW-09). | E22: =IFERROR(INDEX('Task plan'!$G$2:$G$500,MATCH($B22,'Task plan'!$A$2:$A$500,0)),"") | F22: K-01
A24: Machine 3D models from the 360° video (TRELLIS.2 on AWS)
A25: Step | B25: ID | C25: Task | D25: Description | E25: Status today | F25: Depends on | G25: Notes
A26: 18 | B26: L-11 | C26: Pin every TRELLIS.2 version | D26: Pin the TRELLIS.2 commit (75fbf01 when checked) and every CUDA extension it builds (CuMesh, FlexGEMM, nvdiffrast v0.4.0, flash-attn 2.7.3, utils3d), so two image builds are identical. | E26: =IFERROR(INDEX('Task plan'!$G$2:$G$500,MATCH($B26,'Task plan'!$A$2:$A$500,0)),"") | G26: The worker clones main; Microsoft's setup.sh clones CuMesh and FlexGEMM unpinned.
A27: 19 | B27: L-12 | C27: Licence-safe model config | D27: Keep a local copy of the TRELLIS.2-4B config with background removal set to ZhengPeng7/BiRefNet (MIT) instead of briaai/RMBG-2.0 (CC BY-NC 4.0); send our own cut-out so matting is skipped; accept the DINOv3 licence and get access approved on Hugging Face (no product credit is required). | E27: =IFERROR(INDEX('Task plan'!$G$2:$G$500,MATCH($B27,'Task plan'!$A$2:$A$500,0)),"") | G27: TRELLIS.2 loads RMBG-2.0 every time it starts, even when it is not used.
A28: 20 | B28: L-13 | C28: AWS job entrypoint | D28: Replace the RunPod handler loop with an AWS Batch entrypoint: cut-out image from S3 in, GLB and metadata to S3 out, with the model-facing code unchanged. Drop nvdiffrec (preview videos only) and SPCONV_ALGO (a TRELLIS 1 setting) from the image. | E28: =IFERROR(INDEX('Task plan'!$G$2:$G$500,MATCH($B28,'Task plan'!$A$2:$A$500,0)),"") | F28: L-11, L-12 | G28: The RunPod version returns the GLB as base64 inside the job result, which has a size limit.
A29: 21 | B29: L-09 | C29: TRELLIS.2 container | D29: Docker image built for the NVIDIA L40S (CUDA 12.4 build stage, slim runtime) in ECR; weights copied once into S3; stateless entry point: S3 frames in, GLB out. Replaces the RunPod kit. | E29: =IFERROR(INDEX('Task plan'!$G$2:$G$500,MATCH($B29,'Task plan'!$A$2:$A$500,0)),"") | G29: apps/trellis2-worker in the Digital Twin repo: Dockerfile and handler checked against Microsoft's code; needs L-11 to L-13 before use.
A30: 22 | B30: L-10 | C30: GPU environment | D30: AWS Batch on g6e.xlarge in Sydney, scaling to zero when idle; job definition; infrastructure code inside the backend's CDK app. | E30: =IFERROR(INDEX('Task plan'!$G$2:$G$500,MATCH($B30,'Task plan'!$A$2:$A$500,0)),"") | F30: M-02, M-15
A31: 23 | B31: L-14 | C31: Golden test for each image build | D31: Run one fixed image with a fixed seed on every new image; compare triangle count, file size and run time with a stored reference before the image is used. | E31: =IFERROR(INDEX('Task plan'!$G$2:$G$500,MATCH($B31,'Task plan'!$A$2:$A$500,0)),"") | F31: L-10 | G31: TRELLIS.2 has never been run: all 8 saved Digital Twin jobs used TRELLIS 1.
A32: 24 | B32: L-01 | C32: Route test on five machines | D32: Chrome, black rubber, against a wall, in a row, large: compare measured reconstruction with TRELLIS.2 on look, scale error, processing time and file size; recommend the main route. | E32: =IFERROR(INDEX('Task plan'!$G$2:$G$500,MATCH($B32,'Task plan'!$A$2:$A$500,0)),"")
A33: 25 | B33: L-02 | C33: Frame extraction | D33: Pick sharp frames spread around the orbit from the uploaded video, and from the ARKit frames when they exist. | E33: =IFERROR(INDEX('Task plan'!$G$2:$G$500,MATCH($B33,'Task plan'!$A$2:$A$500,0)),"")
A34: 26 | B34: L-03 | C34: Cut-out | D34: Separate the machine from floor, walls and people using segmentation and the machine's scanned box. | E34: =IFERROR(INDEX('Task plan'!$G$2:$G$500,MATCH($B34,'Task plan'!$A$2:$A$500,0)),"") | F34: L-02
A35: 27 | B35: L-05 | C35: Generated route (TRELLIS.2) | D35: Generate a model from the best frame with TRELLIS.2. It accepts one image, so hidden sides are invented. | E35: =IFERROR(INDEX('Task plan'!$G$2:$G$500,MATCH($B35,'Task plan'!$A$2:$A$500,0)),"") | F35: L-03, L-09, O-07
A36: 28 | B36: L-04 | C36: Measured reconstruction | D36: Build a textured mesh from positioned frames and depth. | E36: =IFERROR(INDEX('Task plan'!$G$2:$G$500,MATCH($B36,'Task plan'!$A$2:$A$500,0)),"") | F36: L-03, I-05
A37: 29 | B37: L-06 | C37: Scale, align and optimise | D37: Scale and turn the model to the scanned footprint and facing without stretching (flag large mismatches); levels of detail; compression; store by content hash. | E37: =IFERROR(INDEX('Task plan'!$G$2:$G$500,MATCH($B37,'Task plan'!$A$2:$A$500,0)),"") | F37: L-04 or L-05
A38: 30 | B38: L-07 | C38: Model states and API | D38: asset.build job; states none, queued, building, awaiting review, approved, rejected, failed; API for the editor. | E38: =IFERROR(INDEX('Task plan'!$G$2:$G$500,MATCH($B38,'Task plan'!$A$2:$A$500,0)),"") | F38: E-01, C-15 | G38: Table and the 'asset.build' job kind exist; no handler is registered yet.
A39: 31 | B39: L-08 | C39: Model review screen | D39: In the editor: the model beside its 360° video; approve or reject with a reason; mark a machine 'same as' another to reuse its model. | E39: =IFERROR(INDEX('Task plan'!$G$2:$G$500,MATCH($B39,'Task plan'!$A$2:$A$500,0)),"") | F39: L-07
A40: 32 | B40: J-06 | C40: Machines in the level | D40: Place each approved machine model at its position and facing; a plain box where there is no model; repeated models instanced. | E40: =IFERROR(INDEX('Task plan'!$G$2:$G$500,MATCH($B40,'Task plan'!$A$2:$A$500,0)),"") | F40: J-01, L-07
A41: 33 | B41: K-03 | C41: Machine models in the viewer | D41: Load and cache machine models across levels; lower detail at a distance. | E41: =IFERROR(INDEX('Task plan'!$G$2:$G$500,MATCH($B41,'Task plan'!$A$2:$A$500,0)),"") | F41: K-01, L-06

Sheet Task plan
A1: ID | B1: Area | C1: Task | D1: Description | E1: Owner | F1: Works with | G1: Status today | H1: Depends on | I1: Notes
A2: A-01 | B2: A. Do first: blockers and bugs | C2: Commit the shared plan library | D2: Get shared/plan from its author, commit it and remove /shared/ from .gitignore. 17 files import 34 functions from it; without it the backend cannot start and the web app cannot build. | E2: Thomas | G2: Not started | I2: Missing since the first commit; still missing in 1316d60.
A3: A-02 | B3: A. Do first: blockers and bugs | C3: Make every test suite pass | D3: Run the backend, web and mobile tests and fix what fails. Today 15 of 17 backend and web test files fail; the mobile tests have never been run. | E3: Thomas | G3: Not started | H3: A-01
A4: A-03 | B4: A. Do first: blockers and bugs | C4: Restore CodeCommit access | D4: git fetch returns 403 from the audit machine. Fix access so the whole team works from the latest code. | E4: Thomas | G4: Not started
A5: A-04 | B5: A. Do first: blockers and bugs | C5: Fix the equipment-recording crash | D5: The 360° recorder adds the microphone, but Info.plist declares no microphone permission, so iOS closes the app on the first recording. Remove audio from the recorder; this also keeps members' voices out of stored videos. | E5: Thomas | G5: Not started | I5: EquipmentVideoRecorder.swift lines 107–112.
A6: A-05 | B6: A. Do first: blockers and bugs | C6: Fix account data removal | D6: Removal deletes captures while machine and video rows still point at them, so it fails with a foreign-key error for any account with recorded machines. Delete machines and videos first and add a test that includes machines. | E6: Thomas | G6: Not started | I6: admin.js removal never touches capture_equipment or equipment_videos; the seed has no machines, so the test passes.
A7: A-06 | B7: A. Do first: blockers and bugs | C7: Mac, Xcode and a LiDAR iPhone | D7: Needed for any iPhone build or device test; the current Windows machine cannot build the app. | E7: Product owner | G7: Not started
A8: A-07 | B8: A. Do first: blockers and bugs | C8: First end-to-end device run | D8: From a LiDAR iPhone against a local backend: scan, name machines, record their videos, submit, review, approve. | E8: Thomas | G8: Not started | H8: A-01, A-04, A-06 | I8: No device run has ever happened.
A9: B-01 | B9: B. Single sign-in (GoalCert Hub) and accounts | C9: Hub sign-in exchange | D9: POST /v1/auth/hub: take the Hub's one-time code and PKCE verifier, call the Hub token endpoint with the client secret, verify the signed identity (Hub keys, issuer, audience, expiry, nonce, organisation), then issue Flex tokens with the existing rotating refresh-token code. | E9: Thomas | G9: Not started | H9: C-03, N-02 | I9: auth.js still signs in with passwords.
A10: B-02 | B10: B. Single sign-in (GoalCert Hub) and accounts | C10: Hub events endpoint | D10: POST /v1/hub/events: check the HMAC signature; on user disabled or deleted revoke every Flex session; on user updated refresh name and email; record each event id once so a repeated event is ignored. | E10: Thomas | G10: Not started | H10: B-01
A11: B-03 | B11: B. Single sign-in (GoalCert Hub) and accounts | C11: Remove passwords | D11: Remove password sign-in, password reset and password hashes from the backend, and the password, forgot-password and reset screens from the web app and the iPhone app. | E11: Thomas | G11: Not started | H11: B-01, B-07, B-08
A12: B-04 | B12: B. Single sign-in (GoalCert Hub) and accounts | C12: Several accounts per user | D12: A user can belong to several gym accounts with a role in each. Every request names the account it acts on (X-Account-Id) and the backend checks the membership. Replace req.user.orgId in every module. | E12: Thomas | G12: Not started | H12: C-03 | I12: Affects captures, equipment, capture-uploads, plans, review, profile, facilities and admin.
A13: B-05 | B13: B. Single sign-in (GoalCert Hub) and accounts | C13: Invites | D13: A Flex admin invites an email to an account with a role. The first Hub sign-in with a verified, matching email links that Hub user; from then on the user is matched by Hub user id only, never by email. | E13: Thomas | G13: Not started | H13: C-03
A14: B-06 | B14: B. Single sign-in (GoalCert Hub) and accounts | C14: Session rules | D14: Web: refresh token for the browser tab only. iPhone: 60-day rotating refresh token in the Keychain; a Hub disable or delete signs the phone out. | E14: Thomas | G14: Not started | H14: B-01, O-03
A15: B-07 | B15: B. Single sign-in (GoalCert Hub) and accounts | C15: Web sign-in through the Hub | D15: Login page redirects to the Hub; a callback route sends the code to B-01; account switcher for users in several accounts. | E15: Thomas | G15: Not started | H15: B-01 | I15: LoginPage.jsx is a password form.
A16: B-08 | B16: B. Single sign-in (GoalCert Hub) and accounts | C16: iPhone sign-in through the Hub | D16: ASWebAuthenticationSession with PKCE; tokens in the Keychain; account picker; interrupted uploads resume after relaunch without signing in again. | E16: Thomas | G16: Not started | H16: B-01 | I16: auth_session.dart keeps tokens in memory only.
A17: B-09 | B17: B. Single sign-in (GoalCert Hub) and accounts | C17: Admin screens for invites and roles | D17: Replace 'add user with password' with invites; manage memberships per account and staff roles (reviewer, admin). | E17: Thomas | G17: Not started | H17: B-05
A18: B-10 | B18: B. Single sign-in (GoalCert Hub) and accounts | C18: Tenant isolation tests | D18: Extend the isolation tests: a user in accounts A and B sees B's data only while acting in B; a share link can never reach another plan. | E18: Thomas | G18: Partly built | H18: B-04 | I18: Single-account isolation is already tested, including equipment.
A19: C-01 | B19: C. Database | C19: New baseline schema | D19: Nothing is deployed yet, so replace migrations 001–004 with one clean baseline built to the target schema instead of layering more ALTER statements. | E19: Thomas | F19: Tejesh | G19: Not started
A20: C-02 | B20: C. Database | C20: UUID primary keys | D20: Every primary key becomes a UUIDv7 stored as CHAR(36) ASCII (time-ordered, so inserts stay in index order). Users also keep the Hub user id, unique. | E20: Thomas | G20: Not started | H20: C-01 | I20: Today: prefix plus 20 random characters in VARCHAR(40), e.g. usr_…
A21: C-03 | B21: C. Database | C21: Users, memberships, invites, sessions | D21: Replace users.org_id, role, role_label, password_hash and the password_resets table with the users, memberships, invites and sessions tables of the target schema. | E21: Thomas | G21: Not started | H21: C-01
A22: C-04 | B22: C. Database | C22: Remove redundant columns | D22: Drop users.role_label, plan_versions.walkthrough_url, plan_versions.review_seconds, the copies of coverage, override reason and area on plan_versions, captures.facility_id and level, share_links.plan_version_id and capture_files.equipment_id. | E22: Thomas | G22: Not started | H22: C-01
A23: C-05 | B23: C. Database | C23: Generated measurement columns | D23: Make area, width, length, perimeter, element counts and open-flag count STORED generated columns computed from plan_json, so they can never disagree with the plan. | E23: Thomas | G23: Not started | H23: C-01 | I23: Today they are copied by hand on every write (migration 003).
A24: C-06 | B24: C. Database | C24: Typed capture details | D24: Replace the captures.metadata JSON with typed columns, plus capture_tags, control_distances and drawing_details tables. | E24: Thomas | G24: Not started | H24: C-01
A25: C-07 | B25: C. Database | C25: Equipment types table | D25: Store machine types once in equipment_types (a global list plus custom types per account) instead of free text on every row. | E25: Thomas | G25: Not started | H25: C-01
A26: C-08 | B26: C. Database | C26: Foreign keys and matching account keys | D26: Add the missing foreign keys (plan saved by, based on version, share link plan, video files) and composite (account_id, id) foreign keys so a child row's account always matches its parent's. | E26: Thomas | G26: Not started | H26: C-01
A27: C-09 | B27: C. Database | C27: Uniqueness enforced by the database | D27: One approved or ready version per plan, one unrevoked share link per plan, one open invite per email per account, each Hub event once, one approved model per machine. | E27: Thomas | F27: Tejesh | G27: Not started | H27: C-01 | I27: Today only the code prevents these duplicates.
A28: C-10 | B28: C. Database | C28: Indexes | D28: Reviewer queue (status, submitted_at); weekly reviewer time (reviewed_by, reviewed_at); share links by plan; audit log by target; jobs by status. | E28: Thomas | G28: Not started | H28: C-01
A29: C-11 | B29: C. Database | C29: CHECK constraints | D29: Database checks for ranges the API already validates: level −5 to 200, coverage 0 to 1, positive sizes, quota not negative. | E29: Thomas | G29: Not started | H29: C-01
A30: C-12 | B30: C. Database | C30: UTC everywhere | D30: Set the session time zone to UTC on every connection and use one time function. Today column defaults and NOW() use the server's zone while updates use UTC_TIMESTAMP(). | E30: Thomas | G30: Not started
A31: C-13 | B31: C. Database | C31: Character sets | D31: Declare utf8mb4_0900_ai_ci on every table and ASCII binary on ID columns. Today only 4 of 14 tables declare one. | E31: Thomas | G31: Not started | H31: C-01
A32: C-14 | B32: C. Database | C32: MySQL 8.4 | D32: Move Docker Compose, tests and RDS to MySQL 8.4 LTS; 8.0 is out of support. | E32: Thomas | G32: Not started
A33: C-15 | B33: C. Database | C33: 3D tables | D33: Design and migrate generated_models and machine_models (status, generator version, storage keys, sizes, review) in the shared schema. | E33: Tejesh | F33: Thomas | G33: Done | H33: C-01 | I33: Built by Thomas in backend/migrations/001_baseline.sql (machine_models, generated_models). Review only.
A34: C-16 | B34: C. Database | C34: Seed data | D34: Rewrite the seed for the new schema, including machines, videos, models and users in several accounts. | E34: Thomas | F34: Tejesh | G34: Not started | H34: C-01
A35: D-01 | B35: D. Backend services | C35: Captures module | D35: Account-scoped requests and typed capture details; keep the idempotent register and resumable signed-URL upload. | E35: Thomas | G35: Partly built | H35: B-04, C-06
A36: D-02 | B36: D. Backend services | C36: Equipment module | D36: Use equipment_types and the machines and machine_videos tables; when a video is retaken, delete the old S3 objects and abort the old upload. | E36: Thomas | G36: Partly built | H36: C-07 | I36: A retake deletes the rows only (equipment.js lines 326–330).
A37: D-03 | B37: D. Backend services | C37: Place hand-added machines | D37: Let the reviewer place machines that were added on the phone without a position. Today they are left out of the plan and their videos never reach the editor. | E37: Thomas | G37: Not started | I37: equipment.js line 144 filters them out.
A38: D-04 | B38: D. Backend services | C38: Review module | D38: Keep claim, save, approve, reject and revise. Approval moves the plan to Generating and queues the 3D job instead of going straight to Ready. | E38: Thomas | F38: Tejesh | G38: Partly built | H38: E-01
A39: D-05 | B39: D. Backend services | C39: Owner status | D39: Add the Generating state and each machine's model status; build walkthrough links from configuration instead of storing them. | E39: Thomas | G39: Partly built | H39: C-04
A40: D-06 | B40: D. Backend services | C40: Share links | D40: Store tokens hashed; keep expiry and revoke; open the newest ready version's generated model. | E40: Thomas | G40: Partly built | H40: C-01 | I40: Tokens are stored in plain text today.
...

Sheet Summary
A1: Tasks by owner and status
A3: Owner | B3: Not started | C3: Partly built | D3: In progress | E3: Done | F3: Blocked | G3: Total
A4: Tejesh | B4: =COUNTIFS('Task plan'!$E$2:$E$500,$A4,'Task plan'!$G$2:$G$500,B$3) | C4: =COUNTIFS('Task plan'!$E$2:$E$500,$A4,'Task plan'!$G$2:$G$500,C$3) | D4: =COUNTIFS('Task plan'!$E$2:$E$500,$A4,'Task plan'!$G$2:$G$500,D$3) | E4: =COUNTIFS('Task plan'!$E$2:$E$500,$A4,'Task plan'!$G$2:$G$500,E$3) | F4: =COUNTIFS('Task plan'!$E$2:$E$500,$A4,'Task plan'!$G$2:$G$500,F$3) | G4: =SUM(B4:F4)
A5: Thomas | B5: =COUNTIFS('Task plan'!$E$2:$E$500,$A5,'Task plan'!$G$2:$G$500,B$3) | C5: =COUNTIFS('Task plan'!$E$2:$E$500,$A5,'Task plan'!$G$2:$G$500,C$3) | D5: =COUNTIFS('Task plan'!$E$2:$E$500,$A5,'Task plan'!$G$2:$G$500,D$3) | E5: =COUNTIFS('Task plan'!$E$2:$E$500,$A5,'Task plan'!$G$2:$G$500,E$3) | F5: =COUNTIFS('Task plan'!$E$2:$E$500,$A5,'Task plan'!$G$2:$G$500,F$3) | G5: =SUM(B5:F5)
A6: GoalCert team | B6: =COUNTIFS('Task plan'!$E$2:$E$500,$A6,'Task plan'!$G$2:$G$500,B$3) | C6: =COUNTIFS('Task plan'!$E$2:$E$500,$A6,'Task plan'!$G$2:$G$500,C$3) | D6: =COUNTIFS('Task plan'!$E$2:$E$500,$A6,'Task plan'!$G$2:$G$500,D$3) | E6: =COUNTIFS('Task plan'!$E$2:$E$500,$A6,'Task plan'!$G$2:$G$500,E$3) | F6: =COUNTIFS('Task plan'!$E$2:$E$500,$A6,'Task plan'!$G$2:$G$500,F$3) | G6: =SUM(B6:F6)
A7: Product owner | B7: =COUNTIFS('Task plan'!$E$2:$E$500,$A7,'Task plan'!$G$2:$G$500,B$3) | C7: =COUNTIFS('Task plan'!$E$2:$E$500,$A7,'Task plan'!$G$2:$G$500,C$3) | D7: =COUNTIFS('Task plan'!$E$2:$E$500,$A7,'Task plan'!$G$2:$G$500,D$3) | E7: =COUNTIFS('Task plan'!$E$2:$E$500,$A7,'Task plan'!$G$2:$G$500,E$3) | F7: =COUNTIFS('Task plan'!$E$2:$E$500,$A7,'Task plan'!$G$2:$G$500,F$3) | G7: =SUM(B7:F7)
A8: Legal | B8: =COUNTIFS('Task plan'!$E$2:$E$500,$A8,'Task plan'!$G$2:$G$500,B$3) | C8: =COUNTIFS('Task plan'!$E$2:$E$500,$A8,'Task plan'!$G$2:$G$500,C$3) | D8: =COUNTIFS('Task plan'!$E$2:$E$500,$A8,'Task plan'!$G$2:$G$500,D$3) | E8: =COUNTIFS('Task plan'!$E$2:$E$500,$A8,'Task plan'!$G$2:$G$500,E$3) | F8: =COUNTIFS('Task plan'!$E$2:$E$500,$A8,'Task plan'!$G$2:$G$500,F$3) | G8: =SUM(B8:F8)
A9: Total | B9: =SUM(B4:B8) | C9: =SUM(C4:C8) | D9: =SUM(D4:D8) | E9: =SUM(E4:E8) | F9: =SUM(F4:F8) | G9: =SUM(G4:G8)
A10: Check: rows in Task plan | G10: =COUNTA('Task plan'!$A$2:$A$500)
A13: Tasks by area and owner
A15: Area | B15: Tejesh | C15: Thomas | D15: GoalCert team | E15: Product owner | F15: Legal | G15: Total
A16: A. Do first: blockers and bugs | B16: =COUNTIFS('Task plan'!$B$2:$B$500,$A16,'Task plan'!$E$2:$E$500,B$15) | C16: =COUNTIFS('Task plan'!$B$2:$B$500,$A16,'Task plan'!$E$2:$E$500,C$15) | D16: =COUNTIFS('Task plan'!$B$2:$B$500,$A16,'Task plan'!$E$2:$E$500,D$15) | E16: =COUNTIFS('Task plan'!$B$2:$B$500,$A16,'Task plan'!$E$2:$E$500,E$15) | F16: =COUNTIFS('Task plan'!$B$2:$B$500,$A16,'Task plan'!$E$2:$E$500,F$15) | G16: =SUM(B16:F16)
A17: B. Single sign-in (GoalCert Hub) and accounts | B17: =COUNTIFS('Task plan'!$B$2:$B$500,$A17,'Task plan'!$E$2:$E$500,B$15) | C17: =COUNTIFS('Task plan'!$B$2:$B$500,$A17,'Task plan'!$E$2:$E$500,C$15) | D17: =COUNTIFS('Task plan'!$B$2:$B$500,$A17,'Task plan'!$E$2:$E$500,D$15) | E17: =COUNTIFS('Task plan'!$B$2:$B$500,$A17,'Task plan'!$E$2:$E$500,E$15) | F17: =COUNTIFS('Task plan'!$B$2:$B$500,$A17,'Task plan'!$E$2:$E$500,F$15) | G17: =SUM(B17:F17)
A18: C. Database | B18: =COUNTIFS('Task plan'!$B$2:$B$500,$A18,'Task plan'!$E$2:$E$500,B$15) | C18: =COUNTIFS('Task plan'!$B$2:$B$500,$A18,'Task plan'!$E$2:$E$500,C$15) | D18: =COUNTIFS('Task plan'!$B$2:$B$500,$A18,'Task plan'!$E$2:$E$500,D$15) | E18: =COUNTIFS('Task plan'!$B$2:$B$500,$A18,'Task plan'!$E$2:$E$500,E$15) | F18: =COUNTIFS('Task plan'!$B$2:$B$500,$A18,'Task plan'!$E$2:$E$500,F$15) | G18: =SUM(B18:F18)
A19: D. Backend services | B19: =COUNTIFS('Task plan'!$B$2:$B$500,$A19,'Task plan'!$E$2:$E$500,B$15) | C19: =COUNTIFS('Task plan'!$B$2:$B$500,$A19,'Task plan'!$E$2:$E$500,C$15) | D19: =COUNTIFS('Task plan'!$B$2:$B$500,$A19,'Task plan'!$E$2:$E$500,D$15) | E19: =COUNTIFS('Task plan'!$B$2:$B$500,$A19,'Task plan'!$E$2:$E$500,E$15) | F19: =COUNTIFS('Task plan'!$B$2:$B$500,$A19,'Task plan'!$E$2:$E$500,F$15) | G19: =SUM(B19:F19)
A20: E. Processing pipeline | B20: =COUNTIFS('Task plan'!$B$2:$B$500,$A20,'Task plan'!$E$2:$E$500,B$15) | C20: =COUNTIFS('Task plan'!$B$2:$B$500,$A20,'Task plan'!$E$2:$E$500,C$15) | D20: =COUNTIFS('Task plan'!$B$2:$B$500,$A20,'Task plan'!$E$2:$E$500,D$15) | E20: =COUNTIFS('Task plan'!$B$2:$B$500,$A20,'Task plan'!$E$2:$E$500,E$15) | F20: =COUNTIFS('Task plan'!$B$2:$B$500,$A20,'Task plan'!$E$2:$E$500,F$15) | G20: =SUM(B20:F20)
A21: F. Big rooms: scan to 2D plan | B21: =COUNTIFS('Task plan'!$B$2:$B$500,$A21,'Task plan'!$E$2:$E$500,B$15) | C21: =COUNTIFS('Task plan'!$B$2:$B$500,$A21,'Task plan'!$E$2:$E$500,C$15) | D21: =COUNTIFS('Task plan'!$B$2:$B$500,$A21,'Task plan'!$E$2:$E$500,D$15) | E21: =COUNTIFS('Task plan'!$B$2:$B$500,$A21,'Task plan'!$E$2:$E$500,E$15) | F21: =COUNTIFS('Task plan'!$B$2:$B$500,$A21,'Task plan'!$E$2:$E$500,F$15) | G21: =SUM(B21:F21)
A22: G. 2D plan contents (plan format v2) | B22: =COUNTIFS('Task plan'!$B$2:$B$500,$A22,'Task plan'!$E$2:$E$500,B$15) | C22: =COUNTIFS('Task plan'!$B$2:$B$500,$A22,'Task plan'!$E$2:$E$500,C$15) | D22: =COUNTIFS('Task plan'!$B$2:$B$500,$A22,'Task plan'!$E$2:$E$500,D$15) | E22: =COUNTIFS('Task plan'!$B$2:$B$500,$A22,'Task plan'!$E$2:$E$500,E$15) | F22: =COUNTIFS('Task plan'!$B$2:$B$500,$A22,'Task plan'!$E$2:$E$500,F$15) | G22: =SUM(B22:F22)
A23: H. Reviewer editor (web, 2D) | B23: =COUNTIFS('Task plan'!$B$2:$B$500,$A23,'Task plan'!$E$2:$E$500,B$15) | C23: =COUNTIFS('Task plan'!$B$2:$B$500,$A23,'Task plan'!$E$2:$E$500,C$15) | D23: =COUNTIFS('Task plan'!$B$2:$B$500,$A23,'Task plan'!$E$2:$E$500,D$15) | E23: =COUNTIFS('Task plan'!$B$2:$B$500,$A23,'Task plan'!$E$2:$E$500,E$15) | F23: =COUNTIFS('Task plan'!$B$2:$B$500,$A23,'Task plan'!$E$2:$E$500,F$15) | G23: =SUM(B23:F23)
A24: I. iPhone app | B24: =COUNTIFS('Task plan'!$B$2:$B$500,$A24,'Task plan'!$E$2:$E$500,B$15) | C24: =COUNTIFS('Task plan'!$B$2:$B$500,$A24,'Task plan'!$E$2:$E$500,C$15) | D24: =COUNTIFS('Task plan'!$B$2:$B$500,$A24,'Task plan'!$E$2:$E$500,D$15) | E24: =COUNTIFS('Task plan'!$B$2:$B$500,$A24,'Task plan'!$E$2:$E$500,E$15) | F24: =COUNTIFS('Task plan'!$B$2:$B$500,$A24,'Task plan'!$E$2:$E$500,F$15) | G24: =SUM(B24:F24)
A25: J. 2D to 3D generation | B25: =COUNTIFS('Task plan'!$B$2:$B$500,$A25,'Task plan'!$E$2:$E$500,B$15) | C25: =COUNTIFS('Task plan'!$B$2:$B$500,$A25,'Task plan'!$E$2:$E$500,C$15) | D25: =COUNTIFS('Task plan'!$B$2:$B$500,$A25,'Task plan'!$E$2:$E$500,D$15) | E25: =COUNTIFS('Task plan'!$B$2:$B$500,$A25,'Task plan'!$E$2:$E$500,E$15) | F25: =COUNTIFS('Task plan'!$B$2:$B$500,$A25,'Task plan'!$E$2:$E$500,F$15) | G25: =SUM(B25:F25)
A26: K. Walkthrough viewer (web, 3D) | B26: =COUNTIFS('Task plan'!$B$2:$B$500,$A26,'Task plan'!$E$2:$E$500,B$15) | C26: =COUNTIFS('Task plan'!$B$2:$B$500,$A26,'Task plan'!$E$2:$E$500,C$15) | D26: =COUNTIFS('Task plan'!$B$2:$B$500,$A26,'Task plan'!$E$2:$E$500,D$15) | E26: =COUNTIFS('Task plan'!$B$2:$B$500,$A26,'Task plan'!$E$2:$E$500,E$15) | F26: =COUNTIFS('Task plan'!$B$2:$B$500,$A26,'Task plan'!$E$2:$E$500,F$15) | G26: =SUM(B26:F26)
A27: L. Equipment 3D from the 360° video | B27: =COUNTIFS('Task plan'!$B$2:$B$500,$A27,'Task plan'!$E$2:$E$500,B$15) | C27: =COUNTIFS('Task plan'!$B$2:$B$500,$A27,'Task plan'!$E$2:$E$500,C$15) | D27: =COUNTIFS('Task plan'!$B$2:$B$500,$A27,'Task plan'!$E$2:$E$500,D$15) | E27: =COUNTIFS('Task plan'!$B$2:$B$500,$A27,'Task plan'!$E$2:$E$500,E$15) | F27: =COUNTIFS('Task plan'!$B$2:$B$500,$A27,'Task plan'!$E$2:$E$500,F$15) | G27: =SUM(B27:F27)
... A30: O. Product and legal decisions | B30: =COUNTIFS('Task plan'!$B$2:$B$500,$A30,'Task plan'!$E$2:$E$500,B$15) | C30: =COUNTIFS('Task plan'!$B$2:$B$500,$A30,'Task plan'!$E$2:$E$500,C$15) | D30: =COUNTIFS('Task plan'!$B$2:$B$500,$A30,'Task plan'!$E$2:$E$500,D$15) | E30: =COUNTIFS('Task plan'!$B$2:$B$500,$A30,'Task plan'!$E$2:$E$500,E$15) | F30: =COUNTIFS('Task plan'!$B$2:$B$500,$A30,'Task plan'!$E$2:$E$500,F$15) | G30: =SUM(B30:F30)
A31: Total | B31: =SUM(B16:B30) | C31: =SUM(C16:C30) | D31: =SUM(D16:D30) | E31: =SUM(E16:E30) | F31: =SUM(F16:F30) | G31: =SUM(G16:G30)

Sheet TRELLIS check
A1: Part | B1: What was checked | C1: Microsoft's code / the licence | D1: Digital Twin code | E1: Verdict | F1: Action
A2: TRELLIS.2 worker | B2: Model and pipeline class | C2: microsoft/TRELLIS.2-4B, Trellis2ImageTo3DPipeline | D2: Same | E2: Same
A3: TRELLIS.2 worker | B3: Sparse-structure sampler defaults | C3: 12 steps, guidance 7.5, rescale 0.7, rescale_t 5.0 | D3: Same | E3: Same
A4: TRELLIS.2 worker | B4: Shape sampler defaults | C4: 12, 7.5, 0.5, 3.0 | D4: Same | E4: Same
A5: TRELLIS.2 worker | B5: Texture sampler defaults | C5: 12, 1.0, 0.0, 3.0 | D5: Same | E5: Same
A6: TRELLIS.2 worker | B6: Allowed range of each setting | C6: app.py slider bounds | D6: Same bounds | E6: Same
A7: TRELLIS.2 worker | B7: Resolution to pipeline mapping | C7: 512 → 512, 1024 → 1024_cascade, 1536 → 1536_cascade | D7: Same | E7: Same
A8: TRELLIS.2 worker | B8: Mesh clamp before export | C8: mesh.simplify(16777216) | D8: Same | E8: Same
A9: TRELLIS.2 worker | B9: GLB export arguments | C9: to_glb: aabb ±0.5, remesh True, band 1, project 0; WebP textures | D9: Same (reads the export function's signature to pick the right argument names) | E9: Same
A10: TRELLIS.2 worker | B10: Face and texture defaults | C10: 500,000 faces, 2048 textures (app.py) | D10: Worker: same. The Digital Twin orchestrator sends 1024 textures by default | E10: Small difference | F10: Set it explicitly in our own job
A11: TRELLIS.2 worker | B11: Seed | C11: run() default 42; app.py picks one at random | D11: 1 | E11: Small difference | F11: Store the seed with each model
A12: TRELLIS.2 worker | B12: Background removal | C12: RMBG-2.0 inside run() | D12: Same | E12: Same, but the licence blocks commercial use | F12: L-12
A13: TRELLIS.2 worker | B13: Several images of one object | C13: Not supported by TRELLIS.2 | D13: Extra images ignored | E13: Correct | F13: Pick the best frame
A14: TRELLIS.2 worker | B14: Is Microsoft's code changed? | C14: — | D14: No: it clones Microsoft's repository and runs Microsoft's setup.sh | E14: Same
A15: TRELLIS.2 worker | B15: Version pinning | C15: — | D15: Clones main; extensions unpinned | E15: Not reproducible | F15: L-11
A16: TRELLIS.2 worker | B16: Leftover settings | C16: — | D16: SPCONV_ALGO (TRELLIS 1 only); nvdiffrec built but only used for preview videos | E16: Harmless | F16: L-13
A17: TRELLIS.2 worker | B17: Has it ever run? | C17: — | D17: All 8 saved jobs ran TRELLIS 1 (TRELLIS-image-large) | E17: Never deployed | F17: L-14
A18: TRELLIS 1 worker | B18: Model calls (run, run_multi_image, to_glb) | C18: Microsoft's TRELLIS API | D18: Same | E18: Same
A19: TRELLIS 1 worker | B19: Docker build | C19: Microsoft's setup.sh | D19: Hand-written package list without utils3d, which Microsoft's GLB export imports | E19: Broken as written | F19: Do not use for the gym project
A20: TRELLIS 1 worker | B20: Settings the live endpoint used | C20: 12 steps, simplify 0.95 (example.py) | D20: 25 steps, simplify 0.90 | E20: Not Microsoft's settings | F20: —
A21: Orchestrator | B21: 'faithful' chain | C21: Original image in; the model's own pre- and post-processing | D21: Same | E21: Same
A22: Orchestrator | B22: 'legacy' chain | C22: — | D22: Own matting, sharpening, repair and LODs around the model | E22: Not Microsoft's | F22: Do not use
A23: Orchestrator | B23: Configuration | C23: — | D23: README says the default is 'auto', the code says 'faithful'; texture default 1024 in code, 2048 in .env.example | E23: Inconsistent | F23: Not reused; our backend runs its own job
A24: Orchestrator | B24: Real-world size | C24: Model sits in a ±0.5 unit cube | D24: No scaling | E24: Missing for gyms | F24: L-06
A25: Orchestrator | B25: File size | C25: — | D25: 1–7 MB per model in the saved jobs | E25: Too heavy for 25 MB per level | F25: L-06 (lighter version for the viewer)
A26: Licences | B26: TRELLIS.2 code and weights | C26: MIT | E26: OK
A27: Licences | B27: CuMesh, FlexGEMM, utils3d, flash-attn | C27: MIT / BSD-3 | E27: OK
A28: Licences | B28: DINOv3 (image features, used on every run) | C28: Commercial use allowed; accept the licence (gated, approved by Meta); no product credit required (corrected after reading the licence) | E28: OK with conditions | F28: L-12
A29: Licences | B29: RMBG-2.0 (background removal, loaded every start) | C29: CC BY-NC 4.0: no commercial use without a BRIA agreement | E29: Blocked | F29: L-12 (use ZhengPeng7/BiRefNet, MIT)
A30: Licences | B30: nvdiffrast (texture bake inside to_glb) | C30: NVIDIA licence: research and evaluation only | E30: Blocked until reviewed | F30: O-07 (Legal)
A31: Licences | B31: nvdiffrec | C31: NVIDIA licence | D31: Only for preview videos | E31: Not needed | F31: L-13 (drop it)

Sheet Database findings
A1: # | B1: Severity | C1: Finding | D1: Detail | E1: Fix | F1: Owner
A2: 1 | B2: High | C2: Account data removal fails when machines exist | D2: admin.js deletes captures while capture_equipment and equipment_videos still reference them without cascade, so removal stops with a foreign-key error. The seed has no machines, so the test still passes. | E2: Delete machines and videos first; add a test with machines. | F2: Thomas
A3: 2 | B3: High | C3: User model cannot support single login or several accounts | D3: users has one org_id, one role, a password hash and a globally unique email. | E3: users (keyed by Hub user id) + memberships + invites + sessions. | F3: Thomas
A4: 3 | B4: Medium | C4: IDs are not UUIDs | D4: IDs are a prefix plus 20 random characters in VARCHAR(40), e.g. usr_… They are unguessable but not UUIDs and not time-ordered, so inserts land at random places in each index. | E4: UUIDv7 in CHAR(36) ASCII for every primary key. | F4: Thomas
A5: 4 | B5: Medium | C5: Measurement copies can disagree with the plan | D5: plan_versions stores area, width, length, perimeter, elevation and element counts copied from plan_json; every code path that writes a plan must remember to refresh them. | E5: STORED generated columns computed from plan_json. | F5: Thomas
A6: 5 | B6: Medium | C6: Capture facts stored twice | D6: captures.metadata (JSON) holds coverage, outline closed, override reason, area, tags and photo count; plan_versions stores coverage, override reason and area again. | E6: Typed columns on captures only; versions read them through capture_id. | F6: Thomas
A7: 6 | B7: Medium | C7: Facility and level stored twice | D7: captures.facility_id and level repeat plans.facility_id and level, which the capture reaches through its version. | E7: Drop them from captures. | F7: Thomas
A8: 7 | B8: Medium | C8: A stored URL goes stale | D8: plan_versions.walkthrough_url stores a full link built from today's web domain; moving the web app to the GoalCert subdomain leaves every old row wrong. | E8: Drop the column; build links from configuration. | F8: Thomas
A9: 8 | B9: Low | C9: Values stored twice inside one table | D9: users.role_label repeats what users.role says; plan_versions.review_seconds is a copy of review_active_seconds taken at the decision. | E9: Drop both; derive in code. | F9: Thomas
A10: 9 | B10: Low | C10: Dead column | D10: share_links.plan_version_id has been unused since links moved to plan_id. | E10: Drop it. | F10: Thomas
A11: 10 | B11: Medium | C11: Videos and files point at each other | D11: equipment_videos stores its file ids, and capture_files stores the machine id back (without a foreign key). | E11: Keep one direction: machine_videos → capture_files. | F11: Thomas
A12: 11 | B12: Medium | C12: Machine type is free text on every row | D12: 'treadmill', 'Treadmill' and 'tread mill' are stored as different values, in capture_equipment and in the plan. | E12: equipment_types table (global list + custom per account), referenced by id. | F12: Thomas
A13: 12 | B13: Medium | C13: Two columns with one name and two meanings | D13: capture_equipment.equipment_id is the 'EQ-001' reference, while equipment_videos.equipment_id is capture_equipment.id. | E13: Rename the reference to ref; every column ending in _id is a foreign key. | F13: Thomas
... A25: 24 | B25: Good | C25: What is already right | D25: Unique keys on email, facility name per account, level per facility, version per plan, idempotency key per user, file name per capture, machine reference per capture and one video per machine; tokens stored only as SHA-256; the audit log keeps no foreign keys on purpose so it outlives deleted data. | E25: Keep. | F25: —

Sheet Target schema
A1: Table | B1: Owner | C1: Table purpose | D1: Column | E1: Type | F1: Key / rule | G1: Notes
A2: accounts | B2: Thomas | C2: A gym customer. Replaces organisations. | D2: id | E2: CHAR(36) ascii | F2: PK | G2: UUIDv7
A3: accounts | B3: Thomas | C3: A gym customer. Replaces organisations. | D3: name | E3: VARCHAR(200) | F3: UNIQUE
A4: accounts | B4: Thomas | C4: A gym customer. Replaces organisations. | D4: plan_quota | E4: INT UNSIGNED | G4: New plans per calendar month
A5: accounts | B5: Thomas | C5: A gym customer. Replaces organisations. | D5: status | E5: ENUM('active','removed')
A6: accounts | B6: Thomas | C6: A gym customer. Replaces organisations. | D6: removed_at | E6: DATETIME(3) NULL | G6: Set by account removal (ACC-07)
A7: accounts | B7: Thomas | C7: A gym customer. Replaces organisations. | D7: created_at, updated_at | E7: DATETIME(3) | G7: UTC
A8: users | B8: Thomas | C8: One row per person; the Hub holds the password. | D8: id | E8: CHAR(36) ascii | F8: PK | G8: UUIDv7
A9: users | B9: Thomas | C9: One row per person; the Hub holds the password. | D9: hub_user_id | E9: VARCHAR(64) | F9: UNIQUE | G9: The Hub's id (sub)
A10: users | B10: Thomas | C10: One row per person; the Hub holds the password. | D10: email | E10: VARCHAR(254) | G10: Kept in step with the Hub by events; used for notifications
A11: users | B11: Thomas | C11: One row per person; the Hub holds the password. | D11: name | E11: VARCHAR(200)
A12: users | B12: Thomas | C12: One row per person; the Hub holds the password. | D12: staff_role | E12: ENUM('reviewer','admin') NULL | G12: Flex staff only; sees every account
A13: users | B13: Thomas | C13: One row per person; the Hub holds the password. | D13: status | E13: ENUM('active','disabled')
A14: users | B14: Thomas | C14: One row per person; the Hub holds the password. | D14: last_sign_in_at | E14: DATETIME(3) NULL
A15: users | B15: Thomas | C15: One row per person; the Hub holds the password. | D15: created_at, updated_at | E15: DATETIME(3)
A16: memberships | B16: Thomas | C16: Which gym accounts a user belongs to, and the role in each. | D16: account_id | E16: CHAR(36) | F16: PK, FK accounts
A17: memberships | B17: Thomas | C17: Which gym accounts a user belongs to, and the role in each. | D17: user_id | E17: CHAR(36) | F17: PK, FK users
A18: memberships | B18: Thomas | C18: Which gym accounts a user belongs to, and the role in each. | D18: role | E18: ENUM('owner','surveyor')
A19: memberships | B19: Thomas | C19: Which gym accounts a user belongs to, and the role in each. | D19: created_by | E19: CHAR(36) NULL | F19: FK users
A20: memberships | B20: Thomas | C20: Which gym accounts a user belongs to, and the role in each. | D20: created_at | E20: DATETIME(3)
A21: invites | B21: Thomas | C21: Pending access, matched on first Hub sign-in. | D21: id | E21: CHAR(36) | F21: PK
A22: invites | B22: Thomas | C22: Pending access, matched on first Hub sign-in. | D22: account_id | E22: CHAR(36) | F22: FK accounts
A23: invites | B23: Thomas | C23: Pending access, matched on first Hub sign-in. | D23: email | E23: VARCHAR(254)
A24: invites | B24: Thomas | C24: Pending access, matched on first Hub sign-in. | D24: role | E24: ENUM('owner','surveyor')
A25: invites | B25: Thomas | C25: Pending access, matched on first Hub sign-in. | D25: invited_by | E25: CHAR(36) | F25: FK users
A26: invites | B26: Thomas | C26: Pending access, matched on first Hub sign-in. | D26: expires_at, accepted_at | E26: DATETIME(3) | G26: accepted_at NULL while open
A27: invites | B27: Thomas | C27: Pending access, matched on first Hub sign-in. | D27: accepted_user_id | E27: CHAR(36) NULL | F27: FK users
A28: invites | B28: Thomas | C28: Pending access, matched on first Hub sign-in. | D28: open_email | E28: generated: email while open | F28: UNIQUE (account_id, open_email) | G28: One open invite per email per account
A29: sessions | B29: Thomas | C29: Flex refresh tokens after Hub sign-in. Replaces refresh_tokens. | D29: id | E29: CHAR(36) | F29: PK
A30: sessions | B30: Thomas | C30: Flex refresh tokens after Hub sign-in. Replaces refresh_tokens. | D30: user_id | E30: CHAR(36) | F30: FK users, cascade
A31: sessions | B31: Thomas | C31: Flex refresh tokens after Hub sign-in. Replaces refresh_tokens. | D31: token_hash | E31: CHAR(64) | F31: UNIQUE | G31: SHA-256 only
A32: sessions | B32: Thomas | C32: Flex refresh tokens after Hub sign-in. Replaces refresh_tokens. | D32: client | E32: ENUM('web','ios')
A33: sessions | B33: Thomas | C33: Flex refresh tokens after Hub sign-in. Replaces refresh_tokens. | D33: device_label | E33: VARCHAR(100) NULL
A34: sessions | B34: Thomas | C34: Flex refresh tokens after Hub sign-in. Replaces refresh_tokens. | D34: hub_session_id | E34: VARCHAR(64) | G34: From the Hub identity (sid)
A35: sessions | B35: Thomas | C35: Flex refresh tokens after Hub sign-in. Replaces refresh_tokens. | D35: expires_at, absolute_expires_at, last_used_at, revoked_at | E35: DATETIME(3)
A36: sessions | B36: Thomas | C36: Flex refresh tokens after Hub sign-in. Replaces refresh_tokens. | D36: created_at | E36: DATETIME(3)
A37: user_settings | B37: Thomas | C37: Capture settings per user (unchanged). | D37: user_id | E37: CHAR(36) | F37: PK, FK users
A38: user_settings | B38: Thomas | C38: Capture settings per user (unchanged). | D38: upload_on_mobile_data, warn_before_photos | E38: BOOLEAN
A39: user_settings | B39: Thomas | C39: Capture settings per user (unchanged). | D39: updated_at | E39: DATETIME(3)
A40: hub_events | B40: Thomas | C40: Each Hub event processed once. | D40: event_id | E40: VARCHAR(64) | F40: PK
...

Sheet 2D plan for 3D
A1: Element | B1: Field | C1: 3D uses it for | D1: In gymplan/2 today | E1: Owner
A2: Level | B2: Floor elevation | C2: Stacking floor, walls and ceiling at the right height | D2: Yes (room.elevationM) | E2: Thomas
A3: Level | B3: Default ceiling height | C3: Wall tops where no space or wall height is given | D3: Yes (ceilingHeightM, one per plan) | E3: Thomas
A4: Spaces | B4: Outline polygon, name and kind | C4: Floor and ceiling surfaces per space; labels | D4: No | E4: Thomas
A5: Spaces | B5: Floor finish | C5: Floor material per space (rubber, timber, turf) | D5: No | E5: Thomas
A6: Spaces | B6: Ceiling height and ceiling zones | C6: Raised or dropped ceilings, different heights per room | D6: No | E6: Thomas
A7: Walls | B7: Centre line (start and end points) | C7: Wall position and length | D7: Yes | E7: Thomas
A8: Walls | B8: Height | C8: Wall top | D8: Yes (heightM, from RoomPlan) | E8: Thomas
A9: Walls | B9: Thickness | C9: Wall depth; how openings look in section | D9: Partly (thicknessM, usually blank: RoomPlan sees walls as surfaces) | E9: Thomas
A10: Walls | B10: Kind: exterior, interior, partition, glass | C10: Material and transparency | D10: No | E10: Thomas
A11: Walls | B11: Curve | C11: Curved walls | D11: No | E11: Thomas
A12: Walls | B12: Mirror span (from, to, bottom, top) | C12: Reflective section of a wall | D12: Partly (whole wall only) | E12: Thomas
... A29: Quality | B29: Confidence, source and flags per element | C29: Reviewer checks before approval | D29: Yes | E29: Thomas

Sheet Sign-in review
A1: Feature | B1: How it works today | C1: Verdict
A2: Password sign-in | B2: Email and password checked with bcrypt (12 rounds). Unknown emails get the same answer and the same delay as wrong passwords. Disabled users are refused. 10 attempts per 15 minutes per IP and email. | C2: Correct in the code, but not run: the tests cannot start until shared/plan is back. Replaced by Hub sign-in.
A3: Access tokens | B3: HS256 JWT valid 30 minutes, carrying user, account and role. | C3: Correct. A disabled user keeps access until the token expires (up to 30 minutes).
A4: Refresh tokens | B4: Random, stored only as a SHA-256 hash, replaced on every use. Reusing an old one ends every session of that user. | C4: Correct and well designed. Kept for Flex sessions after Hub sign-in.
A5: Sign-out | B5: Revokes the refresh token. | C5: Correct.
A6: Password reset | B6: Emails a single-use link valid 60 minutes; using it ends every session. | C6: Broken end to end: no email is sent (mailer.js only logs) and the link points to a /reset-password page the web app does not have. Removed with Hub sign-in.
A7: Rate limiting | B7: Counters kept in the memory of one server process. | C7: Does not work with more than one server. Move to WAF.
A8: Web session | B8: Access token in memory, refresh token in the tab's sessionStorage, one refresh at a time. | C8: Correct.
A9: iPhone session | B9: Tokens held in memory only. | C9: Not as intended: the surveyor signs in on every launch, interrupted uploads wait for sign-in, and offline start (APP-13) is impossible.
A10: Roles | B10: Owner and surveyor belong to one account; reviewer and admin see all accounts; checked on every route. | C10: Works for one account per user. Several accounts per user is not supported.
A11: Tenant scoping | B11: Every query filters by the account in the token. | C11: Correct by convention and tested for single accounts, including equipment.
A12: Single login through the GoalCert Hub | B12: — | C12: Missing. This replaces password sign-in and reset.
